Workbook
Name CENTRO: Tablas!$A$14:$A$47
Name corredora: Tablas!$A$57
Name cuentas: Tablas!$E$11:$E$12
Name documentos: Tablas!$E$2:$E$5
Name Empresa: Tablas!$A$4:$A$9
Name LISTA1: Tablas!$J$2:$J$6
Name lista10: Tablas!$J$74:$J$86
Name LISTA11: Tablas!$J$87:$J$90
Name LISTA12: Tablas!$J$91:$J$96
Name LISTA13: Tablas!$J$97:$J$99
Name LISTA14: Tablas!$J$100:$J$107
Name LISTA15: Tablas!#REF!
Name LISTA16: Tablas!#REF!
Name LISTA17: Tablas!#REF!
Name LISTA18: Tablas!#REF!
Name LISTA19: Tablas!$J$108:$J$121
Name LISTA2: Tablas!$J$7:$J$18
Name LISTA20: Tablas!$J$122:$J$136
Name LISTA21: Tablas!$J$137:$J$148
Name LISTA22: Tablas!#REF!
Name LISTA23: Tablas!#REF!
Name LISTA24: Tablas!#REF!
Name LISTA25: Tablas!#REF!
Name LISTA26: Tablas!$J$149:$J$154
Name LISTA27: Tablas!$J$155:$J$160
Name LISTA28: Tablas!$J$161:$J$161
Name LISTA29: Tablas!$J$162:$J$162
Name LISTA3: Tablas!$J$19:$J$25
Name LISTA30: Tablas!$J$163:$J$177
Name LISTA31: Tablas!$J$178:$J$184
Name LISTA32: Tablas!$J$185:$J$186
Name LISTA33: Tablas!$J$187:$J$193
Name LISTA34: Tablas!$J$194:$J$199
Name LISTA35: Tablas!$J$195:$J$199
Name LISTA36: Tablas!$J$200:$J$205
Name LISTA37: Tablas!$J$206:$J$214
Name LISTA38: Tablas!$J$215:$J$221
Name LISTA39: Tablas!$J$222:$J$227
Name LISTA4: Tablas!$J$26:$J$31
Name LISTA40: Tablas!#REF!
Name lista41: Tablas!$J$244:$J$258
Name LISTA42: Tablas!#REF!
Name LISTA43: Tablas!$J$228:$J$235
Name LISTA44: Tablas!$J$236:$J$242
Name LISTA5: Tablas!$J$32:$J$38
Name LISTA6: Tablas!$J$39:$J$46
Name LISTA7: Tablas!$J$47:$J$59
Name LISTA8: Tablas!$J$60:$J$68
Name LISTA9: Tablas!$J$69:$J$73
Name PAGO: Tablas!$C$8:$C$14
Name TABLACC: Tablas!$A$14:$B$47
Name TIPO: Tablas!$F$10:$F$15

Sheet Soliciutd OC
J6: Formulario Solicitud OC
G8: Datos Responsable
H10: Empresa: | I10: Vector Capital Corredora de Bolsa Spa. | P10: Fecha de Solicitud: | R10: =TODAY() -> 46134
H12: Nombre Solicitante: | J12: Victor Nazar
H14: Centro de Costos: | J14: Gerencia
H16: Ítem Presupuesto: | J16: Otros
G18: Datos del Proveedor | H18: Datos del Proveedor
H20: Nombre: | I20: chatGPT, licencia moba xtearm
H22: Dirección:
H24: Comuna: | O24: Rut: | P24: 16138017-2
H26: Correo electrónico:
H28: Nº Cuenta: | I28: 67-10979-1 | P28: Tipo de Cuenta: | Q28: Corriente
H30: Medio de Pago: | I30: Transferencia | O30: Banco: | P30: BANCO SANTANDER
G32: Datos del Contacto
H34: Nombre: | I34: Victor Nazar | P34: Fecha de Pago: | Q34: 45550
H36: Teléfono Fijo: | M36: Documento Asociado: | O36: Boleta de Honorarios(Líquido a Pagar)
H38: Teléfono Móvil: | I38: 56995006161 | P38: Moneda del Monto a Pagar: | Q38: CLP
H40: Indicador: | J40: Tipo de Cambio: | L40: 880 | N40: Total a Pagar: | O40: 199
G42: * En caso de Compartir el Centro de Costo Menciónelo:
H44: Centro de Costo | L44: Item | P44: Monto | R44: Firma
H45: General | L45: 0.15 | P45: 51920
L47: 0 | P47: 87344
P49: 175120
P51: =($O$40/1.19)*L51 -> 0
P53: =($O$40/1.19)*L53 -> 0
H55: Motivo de la Solicitud | O55: Firma Responsable Departamento
H56: Github (licencia mensual IA) CHAT GPT (Licencia mensual IA), Dominio VECTORTRADE.cl (suscripcion anual) INTELLIJ ENTORNO DESARROLLO (SUSCRIPCIÓN ANUAL) | O56: Alonso
H70: =J14 -> Gerencia | I70: ='Soliciutd OC'!H45 -> General | J70: ='Soliciutd OC'!H47 -> 0 | K70: ='Soliciutd OC'!H49 -> 0 | L70: ='Soliciutd OC'!H51 -> 0 | M70: ='Soliciutd OC'!H53 -> 0
H71: =IF(H70="general",Tablas!B57,VLOOKUP(H70,TABLACC,2,FALSE)) -> #N/A | I71: =IFERROR(VLOOKUP(I70,TABLACC,2,FALSE),0) -> LISTA3 | J71: =IFERROR(VLOOKUP(J70,TABLACC,2,FALSE),0) -> 0 | K71: =IFERROR(VLOOKUP(K70,TABLACC,2,FALSE),0) -> 0 | L71: =IFERROR(VLOOKUP(L70,TABLACC,2,FALSE),0) -> 0 | M71: =IFERROR(VLOOKUP(M70,TABLACC,2,FALSE),0) -> 0

Sheet Hoja1
A1: Carmen Sylva 2850 Depto. 32

Sheet Tablas
E1: Documentos | I1: Nombre CC | J1: Nombre Item
A2: Empresas | E2: Factura IVA incluído | I2: Administración | J2: Capacitación Operativa | L2: Administración | M2: Capacitación Operativa
A3: [Seleccione Empresa] | E3: Boleta de Honorarios(Líquido a Pagar) | I3: Administración | J3: Materiales de Oficina | L3: Administración | M3: Materiales de Oficina
A4: Capitaria S.p.A. | E4: Comprobante | I4: Administración | J4: Actividades de Área | L4: Administración | M4: Actividades de Área
A5: Capitaria Latam S.p.A. | E5: Factura exenta | I5: Administración | J5: Otros | L5: Administración | M5: Otros
A6: Vector Capital Corredora de Bolsa Spa. | I6: Administración | J6: Pendiente de Activación
A7: Grupo Capitaria S.p.A. | I7: Capital Humano | J7: Actividades Internas | L7: Capital Humano | M7: Actividades Internas
A8: Global 81 S.p.A. | C8: Caja | I8: Capital Humano | J8: Gestión de Beneficios | L8: Capital Humano | M8: Gestión de Beneficios
A9: KT Financial Group | C9: Cheque | I9: Capital Humano | J9: Reclutamiento y Selección | L9: Capital Humano | M9: Reclutamiento y Selección
C10: Efectivo | F10: CLP | I10: Capital Humano | J10: Desarrollo Organizacional | L10: Capital Humano | M10: Desarrollo Organizacional
C11: Otra | E11: Corriente | F11: EUR | I11: Capital Humano | J11: Capacitación Estratégica | L11: Capital Humano | M11: Capacitación Estratégica
C12: Tarjeta Crédito | E12: Vista | F12: UF | I12: Capital Humano | J12: Honorarios | L12: Capital Humano | M12: Honorarios
A13: Centros de Costo: | C13: Tarjeta Corporativa | F13: PEN | I13: Capital Humano | J13: Capacitación Operativa | L13: Capital Humano | M13: Capacitación Operativa
A14: Mesa Comercial | B14: LISTA1 | C14: Transferencia | F14: GBP | I14: Capital Humano | J14: Materiales de Oficina | L14: Capital Humano | M14: Materiales de Oficina
A15: Mesa Renta Fija | B15: LISTA2 | F15: USD | I15: Capital Humano | J15: Actividades de Área | L15: Capital Humano | M15: Actividades de Área
A16: General | B16: LISTA3 | I16: Capital Humano | J16: Otros | L16: Capital Humano | M16: Otros
A17: Mesa Renta Variable USD | B17: LISTA4 | I17: Capital Humano | J17: Comprometido | L17: Capital Humano | M17: Comprometido
B18: LISTA5 | I18: Capital Humano | J18: Pendiente de Activación
B19: LISTA6 | I19: Compliance | J19: SI - Compliance | L19: Compliance | M19: SI - Compliance
B20: LISTA7 | I20: Compliance | J20: Capacitación Operativa | L20: Compliance | M20: Capacitación Operativa
B21: LISTA8 | I21: Compliance | J21: Materiales de Oficina | L21: Compliance | M21: Materiales de Oficina
A22: GRAF | B22: LISTA9 | D22: NOMBRE BANCO | E22: CÓDIGO | I22: Compliance | J22: Actividades de Área | L22: Compliance | M22: Actividades de Área
A23: Graf Latino | B23: LISTA41 | D23: BANCO BCI | E23: 16 | I23: Compliance | J23: Otros | L23: Compliance | M23: Otros
A24: Graf Latino Perú | B24: LISTA42 | D24: BANCO BICE | E24: 28 | I24: Compliance | J24: Comprometido | L24: Compliance | M24: Comprometido
A25: Graf Latino Uruguay | B25: LISTA43 | D25: BANCO CONSORCIO | E25: 55 | I25: Compliance | J25: Pendiente de Activación
A26: Inglaterra | B26: LISTA30 | D26: BANCO CORPBANCA | E26: 27 | I26: Control de Gestión | J26: SI - Sistemas | L26: Control de Gestión | M26: SI - Sistemas
A27: Marketing | B27: LISTA10 | D27: BANCO CREDICHILE | E27: 1 | I27: Control de Gestión | J27: Capacitación Operativa | L27: Control de Gestión | M27: Capacitación Operativa
A28: Marketing Fidelización de Clientes | B28: LISTA11 | D28: BANCO DE A. EDWARDS | E28: 1 | I28: Control de Gestión | J28: Materiales de Oficina | L28: Control de Gestión | M28: Materiales de Oficina
A29: Marketing Generación de Prospectos | B29: LISTA12 | D29: BANCO DE CHILE | E29: 1 | I29: Control de Gestión | J29: Actividades de Área | L29: Control de Gestión | M29: Actividades de Área
A30: Marketing Otros | B30: LISTA15 | D30: BANCO DEL DESARROLLO | E30: 14 | I30: Control de Gestión | J30: Otros | L30: Control de Gestión | M30: Otros
A31: Marketing Ventas | B31: LISTA13 | D31: BANCO DEL ESTADO DE CHILE | E31: 12 | I31: Control de Gestión | J31: Pendiente de Activación
A32: Mesa De Dinero | B32: LISTA14 | D32: BANCO FALABELLA | E32: 51 | I32: Estrategias de Inversión | J32: Gastos de Representación Comercial | L32: Estrategias de Inversión | M32: Gastos de Representación Comercial
A33: No Op Santiago | B33: LISTA19 | D33: BANCO INTERNACIONAL | E33: 9 | I33: Estrategias de Inversión | J33: Viajes y Viáticos | L33: Estrategias de Inversión | M33: Viajes y Viáticos
A34: No Op Viña del Mar | B34: LISTA20 | D34: BANCO ITAU | E34: 39 | I34: Estrategias de Inversión | J34: Capacitación Operativa | L34: Estrategias de Inversión | M34: Capacitación Operativa
A35: Operaciones | B35: LISTA21 | D35: BANCO ITAÚ CHILE | E35: 39 | I35: Estrategias de Inversión | J35: Materiales de Oficina | L35: Estrategias de Inversión | M35: Materiales de Oficina
A36: Plataforma Santiago 1 | B36: LISTA26 | D36: BANCO SANTANDER | E36: 37 | I36: Estrategias de Inversión | J36: Actividades de Área | L36: Estrategias de Inversión | M36: Actividades de Área
A37: Plataforma Santiago 2 | B37: LISTA27 | D37: BANCO SCOTIABANK | E37: 14 | I37: Estrategias de Inversión | J37: Otros | L37: Estrategias de Inversión | M37: Otros
A38: Plataforma Viña del Mar | B38: LISTA31 | D38: BANCO SECURITY | E38: 49 | I38: Estrategias de Inversión | J38: Pendiente de Activación
A39: Servicio Al Cliente | B39: LISTA33 | D39: BANCO TBANC | E39: 16 | I39: Estudios | J39: SI - Sistemas | L39: Estudios | M39: SI - Sistemas
A40: TI | B40: LISTA34 | D40: BBVA | E40: 14 | I40: Estudios | J40: Servicios Profesionales | L40: Estudios | M40: Servicios Profesionales
...

Sheet BASE PROVEEDORES
A1: RUT | B1: Nombre | C1: CUENTA | D1: CÓDIGO BANCO | E1: CORREO
A2: 132319022 | B2: AGUSTIN LARA | C2: 178448838 | D2: 12 | E2: ALARA@VECTORCAPITAL.CL
A3: 138827399 | B3: RAFAEL VIAL VALENZUELA | C3: 16700304 | D3: 28 | E3: antoniae1@gmail.com
A4: 141203827 | B4: FEDERICO GOYCOOLEA SAEZ | C4: 70305739 | D4: 37 | E4: fgoycoolea@vectorcapital.cl
A5: 177037664 | B5: RODRIGO CASTRO | C5: 17293104 | D5: 1 | E5: rcastro@vectorcapital.cl
A6: 760262706 | B6: MORAGA Y CIA LTDA | C6: 63658030 | D6: 37 | E6: administracion@moragaicia.com
A7: 760625302 | B7: LAROCHE CAPITAL SPA | C7: 1580441805 | D7: 1 | E7: ERIC.VAMBELLE@LAROCHECAPITAL.COM
A8: 761872877 | B8: KHIPU SPA | C8: 66655385 | D8: 37 | E8: hernan.leon@khipu.com
A9: 763431789 | B9: PROTEMPLA CLIMATIZACION Y CIA LTDA | C9: 36071858523 | D9: 12 | E9: cjofre@protempla.cl
A10: 764225864 | B10: ASESORIAS E INVERSIONES THX SPA | C10: 201758901 | D10: 49 | E10: dthenoux@thxinversiones.com
A11: 764625463 | B11: RISKAMERICA | C11: 8810457408 | D11: 1 | E11: fcarcamo@riskamerica.com
A12: 766972365 | B12: SHERPAWMC SPA | C12: 74151477 | D12: 37 | E12: mcc@sherpawmc.cl
A13: 768784760 | B13: AGENCIA DE COMUNICACIONES SMARTPRESS | C13: 220494831 | D13: 39 | E13: elopez@smartpress.cl
... A29: 992890002 | B29: METLIFE CHILE SEGUROS | C29: 2386806 | D29: 1 | E29: lorecontru@gmail.com

Sheet BASE PROVEEDORES BANCO
A1: NOMBRE | B1: RUT | C1: CUENTA | D1: MONTO | E1: CODIGO BANCO | J1: FACTURA | K1: CORREO
A2: =VLOOKUP(B2,'BASE PROVEEDORES'!$A$1:$E$29,2,FALSE) -> AGUSTIN LARA | B2: 132319022 | C2: =VLOOKUP(B2,'BASE PROVEEDORES'!$A$1:$E$29,3,FALSE) -> 178448838 | E2: =VLOOKUP(B2,'BASE PROVEEDORES'!$A$1:$E$29,4,FALSE) -> 12 | F2: 3 | G2: 0 | H2: 1 | I2: 1 | K2: =VLOOKUP(B2,'BASE PROVEEDORES'!$A$1:$E$29,5,FALSE) -> ALARA@VECTORCAPITAL.CL
A3: =VLOOKUP(B3,'BASE PROVEEDORES'!$A$1:$E$29,2,FALSE) -> #N/A | C3: =VLOOKUP(B3,'BASE PROVEEDORES'!$A$1:$E$29,3,FALSE) -> #N/A | E3: =VLOOKUP(B3,'BASE PROVEEDORES'!$A$1:$E$29,4,FALSE) -> #N/A | F3: 3 | G3: 0 | H3: 1 | I3: 1 | K3: =VLOOKUP(B3,'BASE PROVEEDORES'!$A$1:$E$29,5,FALSE) -> #N/A
A4: =VLOOKUP(B4,'BASE PROVEEDORES'!$A$1:$E$29,2,FALSE) -> #N/A | C4: =VLOOKUP(B4,'BASE PROVEEDORES'!$A$1:$E$29,3,FALSE) -> #N/A | E4: =VLOOKUP(B4,'BASE PROVEEDORES'!$A$1:$E$29,4,FALSE) -> #N/A | F4: 3 | G4: 0 | H4: 1 | I4: 1 | K4: =VLOOKUP(B4,'BASE PROVEEDORES'!$A$1:$E$29,5,FALSE) -> #N/A
A5: =VLOOKUP(B5,'BASE PROVEEDORES'!$A$1:$E$29,2,FALSE) -> #N/A | C5: =VLOOKUP(B5,'BASE PROVEEDORES'!$A$1:$E$29,3,FALSE) -> #N/A | E5: =VLOOKUP(B5,'BASE PROVEEDORES'!$A$1:$E$29,4,FALSE) -> #N/A | F5: 3 | G5: 0 | H5: 1 | I5: 1 | K5: =VLOOKUP(B5,'BASE PROVEEDORES'!$A$1:$E$29,5,FALSE) -> #N/A
A6: =VLOOKUP(B6,'BASE PROVEEDORES'!$A$1:$E$29,2,FALSE) -> #N/A | C6: =VLOOKUP(B6,'BASE PROVEEDORES'!$A$1:$E$29,3,FALSE) -> #N/A | E6: =VLOOKUP(B6,'BASE PROVEEDORES'!$A$1:$E$29,4,FALSE) -> #N/A | F6: 3 | G6: 0 | H6: 1 | I6: 1 | K6: =VLOOKUP(B6,'BASE PROVEEDORES'!$A$1:$E$29,5,FALSE) -> #N/A
A7: =VLOOKUP(B7,'BASE PROVEEDORES'!$A$1:$E$29,2,FALSE) -> #N/A | C7: =VLOOKUP(B7,'BASE PROVEEDORES'!$A$1:$E$29,3,FALSE) -> #N/A | E7: =VLOOKUP(B7,'BASE PROVEEDORES'!$A$1:$E$29,4,FALSE) -> #N/A | F7: 3 | G7: 0 | H7: 1 | I7: 1 | K7: =VLOOKUP(B7,'BASE PROVEEDORES'!$A$1:$E$29,5,FALSE) -> #N/A
A8: =VLOOKUP(B8,'BASE PROVEEDORES'!$A$1:$E$29,2,FALSE) -> #N/A | C8: =VLOOKUP(B8,'BASE PROVEEDORES'!$A$1:$E$29,3,FALSE) -> #N/A | E8: =VLOOKUP(B8,'BASE PROVEEDORES'!$A$1:$E$29,4,FALSE) -> #N/A | F8: 3 | G8: 0 | H8: 1 | I8: 1 | K8: =VLOOKUP(B8,'BASE PROVEEDORES'!$A$1:$E$29,5,FALSE) -> #N/A
A9: =VLOOKUP(B9,'BASE PROVEEDORES'!$A$1:$E$29,2,FALSE) -> #N/A | C9: =VLOOKUP(B9,'BASE PROVEEDORES'!$A$1:$E$29,3,FALSE) -> #N/A | E9: =VLOOKUP(B9,'BASE PROVEEDORES'!$A$1:$E$29,4,FALSE) -> #N/A | F9: 3 | G9: 0 | H9: 1 | I9: 1 | K9: =VLOOKUP(B9,'BASE PROVEEDORES'!$A$1:$E$29,5,FALSE) -> #N/A
A10: =VLOOKUP(B10,'BASE PROVEEDORES'!$A$1:$E$29,2,FALSE) -> #N/A | C10: =VLOOKUP(B10,'BASE PROVEEDORES'!$A$1:$E$29,3,FALSE) -> #N/A | E10: =VLOOKUP(B10,'BASE PROVEEDORES'!$A$1:$E$29,4,FALSE) -> #N/A | F10: 3 | G10: 0 | H10: 1 | I10: 1 | K10: =VLOOKUP(B10,'BASE PROVEEDORES'!$A$1:$E$29,5,FALSE) -> #N/A
A11: =VLOOKUP(B11,'BASE PROVEEDORES'!$A$1:$E$29,2,FALSE) -> #N/A | C11: =VLOOKUP(B11,'BASE PROVEEDORES'!$A$1:$E$29,3,FALSE) -> #N/A | E11: =VLOOKUP(B11,'BASE PROVEEDORES'!$A$1:$E$29,4,FALSE) -> #N/A | F11: 3 | G11: 0 | H11: 1 | I11: 1 | K11: =VLOOKUP(B11,'BASE PROVEEDORES'!$A$1:$E$29,5,FALSE) -> #N/A
A12: =VLOOKUP(B12,'BASE PROVEEDORES'!$A$1:$E$29,2,FALSE) -> #N/A | C12: =VLOOKUP(B12,'BASE PROVEEDORES'!$A$1:$E$29,3,FALSE) -> #N/A | E12: =VLOOKUP(B12,'BASE PROVEEDORES'!$A$1:$E$29,4,FALSE) -> #N/A | F12: 3 | G12: 0 | H12: 1 | I12: 1 | K12: =VLOOKUP(B12,'BASE PROVEEDORES'!$A$1:$E$29,5,FALSE) -> #N/A
A13: =VLOOKUP(B13,'BASE PROVEEDORES'!$A$1:$E$29,2,FALSE) -> #N/A | C13: =VLOOKUP(B13,'BASE PROVEEDORES'!$A$1:$E$29,3,FALSE) -> #N/A | E13: =VLOOKUP(B13,'BASE PROVEEDORES'!$A$1:$E$29,4,FALSE) -> #N/A | F13: 3 | G13: 0 | H13: 1 | I13: 1 | K13: =VLOOKUP(B13,'BASE PROVEEDORES'!$A$1:$E$29,5,FALSE) -> #N/A
A14: =VLOOKUP(B14,'BASE PROVEEDORES'!$A$1:$E$29,2,FALSE) -> #N/A | C14: =VLOOKUP(B14,'BASE PROVEEDORES'!$A$1:$E$29,3,FALSE) -> #N/A | E14: =VLOOKUP(B14,'BASE PROVEEDORES'!$A$1:$E$29,4,FALSE) -> #N/A | F14: 3 | G14: 0 | H14: 1 | I14: 1 | K14: =VLOOKUP(B14,'BASE PROVEEDORES'!$A$1:$E$29,5,FALSE) -> #N/A
... A32: =VLOOKUP(B32,'BASE PROVEEDORES'!$A$1:$E$29,2,FALSE) -> #N/A | C32: =VLOOKUP(B32,'BASE PROVEEDORES'!$A$1:$E$29,3,FALSE) -> #N/A | E32: =VLOOKUP(B32,'BASE PROVEEDORES'!$A$1:$E$29,4,FALSE) -> #N/A | F32: 3 | G32: 0 | H32: 1 | I32: 1 | K32: =VLOOKUP(B32,'BASE PROVEEDORES'!$A$1:$E$29,5,FALSE) -> #N/A
